# JUnit5 예외 테스트 (feat. NestedServletException

### 문제 상황
컨트롤러 테스트를 하던 중 RestControllerAdvice를 이용하여 커스텀 예외 처리가 되어야 하는 부분에서
UnverifiedException이 아닌 NestedServletException이 발생하는 문제가 발생하였습니다.

예외 처리를 하고 있는 Service 코드입니다.
~~~java
@Override
public User login(UserDTO.loginForm form) {
    User user = userRepository.findByEmail(form.getEmail()).orElseThrow(() -> new NotFoundException(ErrorCode.NOT_FOUND_USER));

    if(!user.getPassword().equals(form.getPassword())) {
        throw new InvalidPasswordException(ErrorCode.INVALID_PASSWORD);
    }

    if(!user.isVerified()) {
        throw new UnverifiedException(ErrorCode.UNVERIFIED_USER);
    }

    return user;
}
~~~

다음과 같이 RestControllerAdvice를 통해 예외가 터지면 처리할 수 있도록 처리 중입니다.
~~~java
@Slf4j
@RestControllerAdvice
public class GeneralExceptionHandler { }
~~~

### 문제 원인
NestedServletException은 서블릿에서 모든 예외를 처리할 수 있도록 제공하고 있는 클래스입니다. 
커스텀 예외를 처리하기 위해 InvalidVerificationCodeException이라는 클래스를 만들었는데, 이를 위한 핸들러 추가를 하지 않아 발생한 문제였씁니다.

### 문제 해결
다음과 같이 핸들러를 restControolerAdvice 클래스에 추가함으로써 해결할 수 있었습니다.
~~~java
@ExceptionHandler(value = { InvalidVerificationCodeException.class })
protected ResponseEntity<ApiResponse> handleInvalidVerificationCodeException(InvalidVerificationCodeException e) {
    log.error("InvalidPasswordException", e);
    ApiResponse errorResponse = ApiResponse.of(HttpStatus.BAD_REQUEST.toString(), e.getMessage());
    return ResponseEntity.status(e.getErrorCode().getHttpStatus())
            .body(errorResponse);
}
~~~

### NestedSservletException의 예외 해결 추가 방법
1. try-catch를 이용한다.

~~~java
try {
    mockMvc.perform()
    ...
} catch (NestedServletException e) {
    throw e.getCause();    
}
~~~

2. org.assertj.core.api.Assertions.assertThatThrownBy를 사용한다.

~~~java
assertThatThrownBy(() -> mockMvc.perform(post("/login")
            .content(objectMapper.writeValueAsString(request))
            .contentType(MediaType.APPLICATION_JSON)
    )
    .andDo(print()))
    .hasCause(new UnverifiedException(ErrorCode.UNVERIFIED_USER));
~~~

